Workbook

Sheet Comparação salarial
A1: ANÁLISE SALARIAL — CURITIBA / PR
A2: Auxiliar Administrativo Operacional · 2026 · 40 horas semanais · Portaria SMGP nº 4/2026, Anexo B1 — parte permanente; Lei nº 16.198/2023
A3: Referência: Cenário didático: base inicial +5% (cenario). Fonte, competência e decisões: aba Fontes e premissas.
A4: Base da referência: | D4: ='Parâmetros'!B13 -> 2289.46
A5: Continuação das classes/referências: I a XV. Nenhuma classe foi descartada.
A7: ESTRUTURA DE PROMOÇÃO / PROGRESSÃO
A8: AUXILIAR ADMINISTRATIVO OPERACIONAL — 40 HORAS
A9: Classes → | B9: Nível | C9: Regra vertical | D9: I | E9: II | F9: III | G9: IV | H9: V | I9: VI | J9: VII | K9: VIII | L9: IX | M9: X | N9: XI | O9: XII | P9: XIII | Q9: XIV | R9: XV
A10: Níveis ↓ | B10: I | C10: Base | D10: Entrada | E10: ='Parâmetros'!C27/100 -> 0.028 | F10: ='Parâmetros'!C28/100 -> 0.028 | G10: ='Parâmetros'!C29/100 -> 0.028 | H10: ='Parâmetros'!C30/100 -> 0.028 | I10: ='Parâmetros'!C31/100 -> 0.028 | J10: ='Parâmetros'!C32/100 -> 0.028 | K10: ='Parâmetros'!C33/100 -> 0.028 | L10: ='Parâmetros'!C34/100 -> 0.028 | M10: ='Parâmetros'!C35/100 -> 0.028 | N10: ='Parâmetros'!C36/100 -> 0.028 | O10: ='Parâmetros'!C37/100 -> 0.028 | P10: ='Parâmetros'!C38/100 -> 0.028 | Q10: ='Parâmetros'!C39/100 -> 0.028 | R10: ='Parâmetros'!C40/100 -> 0.028
B11: II | C11: ="+"&TEXT('Parâmetros'!D20,"0.00")&IF('Parâmetros'!C20="valor_fixo"," R$ / ","% / ")&'Parâmetros'!E20 -> +15.00% / I | D11: Entrada | E11: ='Parâmetros'!C27/100 -> 0.028 | F11: ='Parâmetros'!C28/100 -> 0.028 | G11: ='Parâmetros'!C29/100 -> 0.028 | H11: ='Parâmetros'!C30/100 -> 0.028 | I11: ='Parâmetros'!C31/100 -> 0.028 | J11: ='Parâmetros'!C32/100 -> 0.028 | K11: ='Parâmetros'!C33/100 -> 0.028 | L11: ='Parâmetros'!C34/100 -> 0.028 | M11: ='Parâmetros'!C35/100 -> 0.028 | N11: ='Parâmetros'!C36/100 -> 0.028 | O11: ='Parâmetros'!C37/100 -> 0.028 | P11: ='Parâmetros'!C38/100 -> 0.028 | Q11: ='Parâmetros'!C39/100 -> 0.028 | R11: ='Parâmetros'!C40/100 -> 0.028
B12: III | C12: ="+"&TEXT('Parâmetros'!D21,"0.00")&IF('Parâmetros'!C21="valor_fixo"," R$ / ","% / ")&'Parâmetros'!E21 -> +15.00% / II | D12: Entrada | E12: ='Parâmetros'!C27/100 -> 0.028 | F12: ='Parâmetros'!C28/100 -> 0.028 | G12: ='Parâmetros'!C29/100 -> 0.028 | H12: ='Parâmetros'!C30/100 -> 0.028 | I12: ='Parâmetros'!C31/100 -> 0.028 | J12: ='Parâmetros'!C32/100 -> 0.028 | K12: ='Parâmetros'!C33/100 -> 0.028 | L12: ='Parâmetros'!C34/100 -> 0.028 | M12: ='Parâmetros'!C35/100 -> 0.028 | N12: ='Parâmetros'!C36/100 -> 0.028 | O12: ='Parâmetros'!C37/100 -> 0.028 | P12: ='Parâmetros'!C38/100 -> 0.028 | Q12: ='Parâmetros'!C39/100 -> 0.028 | R12: ='Parâmetros'!C40/100 -> 0.028
B13: IV | C13: ="+"&TEXT('Parâmetros'!D22,"0.00")&IF('Parâmetros'!C22="valor_fixo"," R$ / ","% / ")&'Parâmetros'!E22 -> +15.00% / III | D13: Entrada | E13: ='Parâmetros'!C27/100 -> 0.028 | F13: ='Parâmetros'!C28/100 -> 0.028 | G13: ='Parâmetros'!C29/100 -> 0.028 | H13: ='Parâmetros'!C30/100 -> 0.028 | I13: ='Parâmetros'!C31/100 -> 0.028 | J13: ='Parâmetros'!C32/100 -> 0.028 | K13: ='Parâmetros'!C33/100 -> 0.028 | L13: ='Parâmetros'!C34/100 -> 0.028 | M13: ='Parâmetros'!C35/100 -> 0.028 | N13: ='Parâmetros'!C36/100 -> 0.028 | O13: ='Parâmetros'!C37/100 -> 0.028 | P13: ='Parâmetros'!C38/100 -> 0.028 | Q13: ='Parâmetros'!C39/100 -> 0.028 | R13: ='Parâmetros'!C40/100 -> 0.028
A16: • TABELA DE VENCIMENTOS 2026 •
A17: AUXILIAR ADMINISTRATIVO OPERACIONAL — 40 HORAS
A18: Classes → | B18: Nível | C18: Regra vertical | D18: I | E18: II | F18: III | G18: IV | H18: V | I18: VI | J18: VII | K18: VIII | L18: IX | M18: X | N18: XI | O18: XII | P18: XIII | Q18: XIV | R18: XV
A19: Níveis ↓ | B19: I | C19: Base | D19: ='Dados originais'!D4 -> 2180.44 | E19: ='Dados originais'!E4 -> 2241.49 | F19: ='Dados originais'!F4 -> 2304.25 | G19: ='Dados originais'!G4 -> 2368.77 | H19: ='Dados originais'!H4 -> 2435.1 | I19: ='Dados originais'!I4 -> 2503.28 | J19: ='Dados originais'!J4 -> 2573.37 | K19: ='Dados originais'!K4 -> 2645.43 | ... R19: ='Dados originais'!R4 -> 3209.58
B20: II | C20: ="+"&TEXT('Parâmetros'!D20,"0.00")&IF('Parâmetros'!C20="valor_fixo"," R$ / ","% / ")&'Parâmetros'!E20 -> +15.00% / I | D20: ='Dados originais'!D5 -> 2507.51 | E20: ='Dados originais'!E5 -> 2577.72 | F20: ='Dados originais'!F5 -> 2649.89 | G20: ='Dados originais'!G5 -> 2724.09 | H20: ='Dados originais'!H5 -> 2800.36 | I20: ='Dados originais'!I5 -> 2878.77 | J20: ='Dados originais'!J5 -> 2959.38 | K20: ='Dados originais'!K5 -> 3042.24 | ... R20: ='Dados originais'!R5 -> 3691.01
B21: III | C21: ="+"&TEXT('Parâmetros'!D21,"0.00")&IF('Parâmetros'!C21="valor_fixo"," R$ / ","% / ")&'Parâmetros'!E21 -> +15.00% / II | D21: ='Dados originais'!D6 -> 2883.63 | E21: ='Dados originais'!E6 -> 2964.37 | F21: ='Dados originais'!F6 -> 3047.38 | G21: ='Dados originais'!G6 -> 3132.7 | H21: ='Dados originais'!H6 -> 3220.42 | I21: ='Dados originais'!I6 -> 3310.59 | J21: ='Dados originais'!J6 -> 3403.29 | K21: ='Dados originais'!K6 -> 3498.58 | ... R21: ='Dados originais'!R6 -> 4244.67
B22: IV | C22: ="+"&TEXT('Parâmetros'!D22,"0.00")&IF('Parâmetros'!C22="valor_fixo"," R$ / ","% / ")&'Parâmetros'!E22 -> +15.00% / III | D22: ='Dados originais'!D7 -> 3316.18 | E22: ='Dados originais'!E7 -> 3409.03 | F22: ='Dados originais'!F7 -> 3504.48 | G22: ='Dados originais'!G7 -> 3602.61 | H22: ='Dados originais'!H7 -> 3703.48 | I22: ='Dados originais'!I7 -> 3807.18 | J22: ='Dados originais'!J7 -> 3913.78 | K22: ='Dados originais'!K7 -> 4023.37 | ... R22: ='Dados originais'!R7 -> 4881.37
A25: • TABELA DE VENCIMENTOS — REFERÊNCIA Cenário didático: base inicial +5% •
A26: AUXILIAR ADMINISTRATIVO OPERACIONAL — 40 HORAS
A27: Classes → | B27: Nível | C27: Regra vertical | D27: I | E27: II | F27: III | G27: IV | H27: V | I27: VI | J27: VII | K27: VIII | L27: IX | M27: X | N27: XI | O27: XII | P27: XIII | Q27: XIV | R27: XV
A28: Níveis ↓ | B28: I | C28: Base | D28: ='Parâmetros'!B13 -> 2289.46 | E28: =IF('Parâmetros'!$B$12="truncar",ROUNDDOWN(D28*(1+'Parâmetros'!C27/100),2),ROUND(D28*(1+'Parâmetros'!C27/100),2)) -> 2353.56 | F28: =IF('Parâmetros'!$B$12="truncar",ROUNDDOWN(E28*(1+'Parâmetros'!C28/100),2),ROUND(E28*(1+'Parâmetros'!C28/100),2)) -> 2419.46 | G28: =IF('Parâmetros'!$B$12="truncar",ROUNDDOWN(F28*(1+'Parâmetros'!C29/100),2),ROUND(F28*(1+'Parâmetros'!C29/100),2)) -> 2487.2 | H28: =IF('Parâmetros'!$B$12="truncar",ROUNDDOWN(G28*(1+'Parâmetros'!C30/100),2),ROUND(G28*(1+'Parâmetros'!C30/100),2)) -> 2556.84 | I28: =IF('Parâmetros'!$B$12="truncar",ROUNDDOWN(H28*(1+'Parâmetros'!C31/100),2),ROUND(H28*(1+'Parâmetros'!C31/100),2)) -> 2628.43 | J28: =IF('Parâmetros'!$B$12="truncar",ROUNDDOWN(I28*(1+'Parâmetros'!C32/100),2),ROUND(I28*(1+'Parâmetros'!C32/100),2)) -> 2702.03 | K28: =IF('Parâmetros'!$B$12="truncar",ROUNDDOWN(J28*(1+'Parâmetros'!C33/100),2),ROUND(J28*(1+'Parâmetros'!C33/100),2)) -> 2777.69 | L28: =IF('Parâmetros'!$B$12="truncar",ROUNDDOWN(K28*(1+'Parâmetros'!C34/100),2),ROUND(K28*(1+'Parâmetros'!C34/100),2)) -> 2855.47 | M28: =IF('Parâmetros'!$B$12="truncar",ROUNDDOWN(L28*(1+'Parâmetros'!C35/100),2),ROUND(L28*(1+'Parâmetros'!C35/100),2)) -> 2935.42 | N28: =IF('Parâmetros'!$B$12="truncar",ROUNDDOWN(M28*(1+'Parâmetros'!C36/100),2),ROUND(M28*(1+'Parâmetros'!C36/100),2)) -> 3017.61 | O28: =IF('Parâmetros'!$B$12="truncar",ROUNDDOWN(N28*(1+'Parâmetros'!C37/100),2),ROUND(N28*(1+'Parâmetros'!C37/100),2)) -> 3102.1 | P28: =IF('Parâmetros'!$B$12="truncar",ROUNDDOWN(O28*(1+'Parâmetros'!C38/100),2),ROUND(O28*(1+'Parâmetros'!C38/100),2)) -> 3188.96 | Q28: =IF('Parâmetros'!$B$12="truncar",ROUNDDOWN(P28*(1+'Parâmetros'!C39/100),2),ROUND(P28*(1+'Parâmetros'!C39/100),2)) -> 3278.25 | R28: =IF('Parâmetros'!$B$12="truncar",ROUNDDOWN(Q28*(1+'Parâmetros'!C40/100),2),ROUND(Q28*(1+'Parâmetros'!C40/100),2)) -> 3370.04
B29: II | C29: ="+"&TEXT('Parâmetros'!D20,"0.00")&IF('Parâmetros'!C20="valor_fixo"," R$ / ","% / ")&'Parâmetros'!E20 -> +15.00% / I | D29: =IF('Parâmetros'!$B$12="truncar",ROUNDDOWN(IF('Parâmetros'!C20="valor_fixo",SUMIF('Parâmetros'!$A$19:$A$19,'Parâmetros'!E20,$D$28:$D$28)+'Parâmetros'!D20,SUMIF('Parâmetros'!$A$19:$A$19,'Parâmetros'!E20,$D$28:$D$28)*(1+'Parâmetros'!D20/100)),2),ROUND(IF('Parâmetros'!C20="valor_fixo",SUMIF('Parâmetros'!$A$19:$A$19,'Parâmetros'!E20,$D$28:$D$28)+'Parâmetros'!D20,SUMIF('Parâmetros'!$A$19:$A$19,'Parâmetros'!E20,$D$28:$D$28)*(1+'Parâmetros'!D20/100)),2)) -> 2632.88 | E29: =IF('Parâmetros'!$B$12="truncar",ROUNDDOWN(D29*(1+'Parâmetros'!C27/100),2),ROUND(D29*(1+'Parâmetros'!C27/100),2)) -> 2706.6 | F29: =IF('Parâmetros'!$B$12="truncar",ROUNDDOWN(E29*(1+'Parâmetros'!C28/100),2),ROUND(E29*(1+'Parâmetros'!C28/100),2)) -> 2782.38 | G29: =IF('Parâmetros'!$B$12="truncar",ROUNDDOWN(F29*(1+'Parâmetros'!C29/100),2),ROUND(F29*(1+'Parâmetros'!C29/100),2)) -> 2860.29 | H29: =IF('Parâmetros'!$B$12="truncar",ROUNDDOWN(G29*(1+'Parâmetros'!C30/100),2),ROUND(G29*(1+'Parâmetros'!C30/100),2)) -> 2940.38 | I29: =IF('Parâmetros'!$B$12="truncar",ROUNDDOWN(H29*(1+'Parâmetros'!C31/100),2),ROUND(H29*(1+'Parâmetros'!C31/100),2)) -> 3022.71 | J29: =IF('Parâmetros'!$B$12="truncar",ROUNDDOWN(I29*(1+'Parâmetros'!C32/100),2),ROUND(I29*(1+'Parâmetros'!C32/100),2)) -> 3107.35 | K29: =IF('Parâmetros'!$B$12="truncar",ROUNDDOWN(J29*(1+'Parâmetros'!C33/100),2),ROUND(J29*(1+'Parâmetros'!C33/100),2)) -> 3194.36 | L29: =IF('Parâmetros'!$B$12="truncar",ROUNDDOWN(K29*(1+'Parâmetros'!C34/100),2),ROUND(K29*(1+'Parâmetros'!C34/100),2)) -> 3283.8 | M29: =IF('Parâmetros'!$B$12="truncar",ROUNDDOWN(L29*(1+'Parâmetros'!C35/100),2),ROUND(L29*(1+'Parâmetros'!C35/100),2)) -> 3375.75 | N29: =IF('Parâmetros'!$B$12="truncar",ROUNDDOWN(M29*(1+'Parâmetros'!C36/100),2),ROUND(M29*(1+'Parâmetros'!C36/100),2)) -> 3470.27 | O29: =IF('Parâmetros'!$B$12="truncar",ROUNDDOWN(N29*(1+'Parâmetros'!C37/100),2),ROUND(N29*(1+'Parâmetros'!C37/100),2)) -> 3567.44 | P29: =IF('Parâmetros'!$B$12="truncar",ROUNDDOWN(O29*(1+'Parâmetros'!C38/100),2),ROUND(O29*(1+'Parâmetros'!C38/100),2)) -> 3667.33 | Q29: =IF('Parâmetros'!$B$12="truncar",ROUNDDOWN(P29*(1+'Parâmetros'!C39/100),2),ROUND(P29*(1+'Parâmetros'!C39/100),2)) -> 3770.02 | R29: =IF('Parâmetros'!$B$12="truncar",ROUNDDOWN(Q29*(1+'Parâmetros'!C40/100),2),ROUND(Q29*(1+'Parâmetros'!C40/100),2)) -> 3875.58
B30: III | C30: ="+"&TEXT('Parâmetros'!D21,"0.00")&IF('Parâmetros'!C21="valor_fixo"," R$ / ","% / ")&'Parâmetros'!E21 -> +15.00% / II | D30: =IF('Parâmetros'!$B$12="truncar",ROUNDDOWN(IF('Parâmetros'!C21="valor_fixo",SUMIF('Parâmetros'!$A$19:$A$20,'Parâmetros'!E21,$D$28:$D$29)+'Parâmetros'!D21,SUMIF('Parâmetros'!$A$19:$A$20,'Parâmetros'!E21,$D$28:$D$29)*(1+'Parâmetros'!D21/100)),2),ROUND(IF('Parâmetros'!C21="valor_fixo",SUMIF('Parâmetros'!$A$19:$A$20,'Parâmetros'!E21,$D$28:$D$29)+'Parâmetros'!D21,SUMIF('Parâmetros'!$A$19:$A$20,'Parâmetros'!E21,$D$28:$D$29)*(1+'Parâmetros'!D21/100)),2)) -> 3027.81 | E30: =IF('Parâmetros'!$B$12="truncar",ROUNDDOWN(D30*(1+'Parâmetros'!C27/100),2),ROUND(D30*(1+'Parâmetros'!C27/100),2)) -> 3112.59 | F30: =IF('Parâmetros'!$B$12="truncar",ROUNDDOWN(E30*(1+'Parâmetros'!C28/100),2),ROUND(E30*(1+'Parâmetros'!C28/100),2)) -> 3199.74 | G30: =IF('Parâmetros'!$B$12="truncar",ROUNDDOWN(F30*(1+'Parâmetros'!C29/100),2),ROUND(F30*(1+'Parâmetros'!C29/100),2)) -> 3289.33 | H30: =IF('Parâmetros'!$B$12="truncar",ROUNDDOWN(G30*(1+'Parâmetros'!C30/100),2),ROUND(G30*(1+'Parâmetros'!C30/100),2)) -> 3381.43 | I30: =IF('Parâmetros'!$B$12="truncar",ROUNDDOWN(H30*(1+'Parâmetros'!C31/100),2),ROUND(H30*(1+'Parâmetros'!C31/100),2)) -> 3476.11 | J30: =IF('Parâmetros'!$B$12="truncar",ROUNDDOWN(I30*(1+'Parâmetros'!C32/100),2),ROUND(I30*(1+'Parâmetros'!C32/100),2)) -> 3573.44 | K30: =IF('Parâmetros'!$B$12="truncar",ROUNDDOWN(J30*(1+'Parâmetros'!C33/100),2),ROUND(J30*(1+'Parâmetros'!C33/100),2)) -> 3673.5 | L30: =IF('Parâmetros'!$B$12="truncar",ROUNDDOWN(K30*(1+'Parâmetros'!C34/100),2),ROUND(K30*(1+'Parâmetros'!C34/100),2)) -> 3776.36 | M30: =IF('Parâmetros'!$B$12="truncar",ROUNDDOWN(L30*(1+'Parâmetros'!C35/100),2),ROUND(L30*(1+'Parâmetros'!C35/100),2)) -> 3882.1 | N30: =IF('Parâmetros'!$B$12="truncar",ROUNDDOWN(M30*(1+'Parâmetros'!C36/100),2),ROUND(M30*(1+'Parâmetros'!C36/100),2)) -> 3990.8 | O30: =IF('Parâmetros'!$B$12="truncar",ROUNDDOWN(N30*(1+'Parâmetros'!C37/100),2),ROUND(N30*(1+'Parâmetros'!C37/100),2)) -> 4102.54 | P30: =IF('Parâmetros'!$B$12="truncar",ROUNDDOWN(O30*(1+'Parâmetros'!C38/100),2),ROUND(O30*(1+'Parâmetros'!C38/100),2)) -> 4217.41 | Q30: =IF('Parâmetros'!$B$12="truncar",ROUNDDOWN(P30*(1+'Parâmetros'!C39/100),2),ROUND(P30*(1+'Parâmetros'!C39/100),2)) -> 4335.5 | R30: =IF('Parâmetros'!$B$12="truncar",ROUNDDOWN(Q30*(1+'Parâmetros'!C40/100),2),ROUND(Q30*(1+'Parâmetros'!C40/100),2)) -> 4456.89
B31: IV | C31: ="+"&TEXT('Parâmetros'!D22,"0.00")&IF('Parâmetros'!C22="valor_fixo"," R$ / ","% / ")&'Parâmetros'!E22 -> +15.00% / III | D31: =IF('Parâmetros'!$B$12="truncar",ROUNDDOWN(IF('Parâmetros'!C22="valor_fixo",SUMIF('Parâmetros'!$A$19:$A$21,'Parâmetros'!E22,$D$28:$D$30)+'Parâmetros'!D22,SUMIF('Parâmetros'!$A$19:$A$21,'Parâmetros'!E22,$D$28:$D$30)*(1+'Parâmetros'!D22/100)),2),ROUND(IF('Parâmetros'!C22="valor_fixo",SUMIF('Parâmetros'!$A$19:$A$21,'Parâmetros'!E22,$D$28:$D$30)+'Parâmetros'!D22,SUMIF('Parâmetros'!$A$19:$A$21,'Parâmetros'!E22,$D$28:$D$30)*(1+'Parâmetros'!D22/100)),2)) -> 3481.98 | E31: =IF('Parâmetros'!$B$12="truncar",ROUNDDOWN(D31*(1+'Parâmetros'!C27/100),2),ROUND(D31*(1+'Parâmetros'!C27/100),2)) -> 3579.48 | F31: =IF('Parâmetros'!$B$12="truncar",ROUNDDOWN(E31*(1+'Parâmetros'!C28/100),2),ROUND(E31*(1+'Parâmetros'!C28/100),2)) -> 3679.71 | G31: =IF('Parâmetros'!$B$12="truncar",ROUNDDOWN(F31*(1+'Parâmetros'!C29/100),2),ROUND(F31*(1+'Parâmetros'!C29/100),2)) -> 3782.74 | H31: =IF('Parâmetros'!$B$12="truncar",ROUNDDOWN(G31*(1+'Parâmetros'!C30/100),2),ROUND(G31*(1+'Parâmetros'!C30/100),2)) -> 3888.66 | I31: =IF('Parâmetros'!$B$12="truncar",ROUNDDOWN(H31*(1+'Parâmetros'!C31/100),2),ROUND(H31*(1+'Parâmetros'!C31/100),2)) -> 3997.54 | J31: =IF('Parâmetros'!$B$12="truncar",ROUNDDOWN(I31*(1+'Parâmetros'!C32/100),2),ROUND(I31*(1+'Parâmetros'!C32/100),2)) -> 4109.47 | K31: =IF('Parâmetros'!$B$12="truncar",ROUNDDOWN(J31*(1+'Parâmetros'!C33/100),2),ROUND(J31*(1+'Parâmetros'!C33/100),2)) -> 4224.54 | L31: =IF('Parâmetros'!$B$12="truncar",ROUNDDOWN(K31*(1+'Parâmetros'!C34/100),2),ROUND(K31*(1+'Parâmetros'!C34/100),2)) -> 4342.83 | M31: =IF('Parâmetros'!$B$12="truncar",ROUNDDOWN(L31*(1+'Parâmetros'!C35/100),2),ROUND(L31*(1+'Parâmetros'!C35/100),2)) -> 4464.43 | N31: =IF('Parâmetros'!$B$12="truncar",ROUNDDOWN(M31*(1+'Parâmetros'!C36/100),2),ROUND(M31*(1+'Parâmetros'!C36/100),2)) -> 4589.43 | O31: =IF('Parâmetros'!$B$12="truncar",ROUNDDOWN(N31*(1+'Parâmetros'!C37/100),2),ROUND(N31*(1+'Parâmetros'!C37/100),2)) -> 4717.93 | P31: =IF('Parâmetros'!$B$12="truncar",ROUNDDOWN(O31*(1+'Parâmetros'!C38/100),2),ROUND(O31*(1+'Parâmetros'!C38/100),2)) -> 4850.03 | Q31: =IF('Parâmetros'!$B$12="truncar",ROUNDDOWN(P31*(1+'Parâmetros'!C39/100),2),ROUND(P31*(1+'Parâmetros'!C39/100),2)) -> 4985.83 | R31: =IF('Parâmetros'!$B$12="truncar",ROUNDDOWN(Q31*(1+'Parâmetros'!C40/100),2),ROUND(Q31*(1+'Parâmetros'!C40/100),2)) -> 5125.43
A34: ="Neste bloco: "&SUMPRODUCT(--(D19:R22<D28:R31))&" vencimentos abaixo da referência de carreira; "&COUNTIF(D19:R22,"<"&$D$4)&" abaixo da base inicial (em vermelho)." -> Neste bloco: 60 vencimentos abaixo da referência de carreira; 2 abaixo da base inicial (em vermelho).
A36: NÃO CONFORMIDADES EM RELAÇÃO À REFERÊNCIA
A37: AUXILIAR ADMINISTRATIVO OPERACIONAL — 40 HORAS
A38: Classes → | B38: Nível | C38: Regra vertical | D38: I | E38: II | F38: III | G38: IV | H38: V | I38: VI | J38: VII | K38: VIII | L38: IX | M38: X | N38: XI | O38: XII | P38: XIII | Q38: XIV | R38: XV
A39: Níveis ↓ | B39: I | C39: Base | D39: ='Dados originais'!D4 -> 2180.44 | E39: ='Dados originais'!E4 -> 2241.49 | F39: ='Dados originais'!F4 -> 2304.25 | G39: ='Dados originais'!G4 -> 2368.77 | H39: ='Dados originais'!H4 -> 2435.1 | I39: ='Dados originais'!I4 -> 2503.28 | J39: ='Dados originais'!J4 -> 2573.37 | K39: ='Dados originais'!K4 -> 2645.43 | ... R39: ='Dados originais'!R4 -> 3209.58
B40: II | C40: ="+"&TEXT('Parâmetros'!D20,"0.00")&IF('Parâmetros'!C20="valor_fixo"," R$ / ","% / ")&'Parâmetros'!E20 -> +15.00% / I | D40: ='Dados originais'!D5 -> 2507.51 | E40: ='Dados originais'!E5 -> 2577.72 | F40: ='Dados originais'!F5 -> 2649.89 | G40: ='Dados originais'!G5 -> 2724.09 | H40: ='Dados originais'!H5 -> 2800.36 | I40: ='Dados originais'!I5 -> 2878.77 | J40: ='Dados originais'!J5 -> 2959.38 | K40: ='Dados originais'!K5 -> 3042.24 | ... R40: ='Dados originais'!R5 -> 3691.01
B41: III | C41: ="+"&TEXT('Parâmetros'!D21,"0.00")&IF('Parâmetros'!C21="valor_fixo"," R$ / ","% / ")&'Parâmetros'!E21 -> +15.00% / II | D41: ='Dados originais'!D6 -> 2883.63 | E41: ='Dados originais'!E6 -> 2964.37 | F41: ='Dados originais'!F6 -> 3047.38 | G41: ='Dados originais'!G6 -> 3132.7 | H41: ='Dados originais'!H6 -> 3220.42 | I41: ='Dados originais'!I6 -> 3310.59 | J41: ='Dados originais'!J6 -> 3403.29 | K41: ='Dados originais'!K6 -> 3498.58 | ... R41: ='Dados originais'!R6 -> 4244.67
B42: IV | C42: ="+"&TEXT('Parâmetros'!D22,"0.00")&IF('Parâmetros'!C22="valor_fixo"," R$ / ","% / ")&'Parâmetros'!E22 -> +15.00% / III | D42: ='Dados originais'!D7 -> 3316.18 | E42: ='Dados originais'!E7 -> 3409.03 | F42: ='Dados originais'!F7 -> 3504.48 | G42: ='Dados originais'!G7 -> 3602.61 | H42: ='Dados originais'!H7 -> 3703.48 | I42: ='Dados originais'!I7 -> 3807.18 | J42: ='Dados originais'!J7 -> 3913.78 | K42: ='Dados originais'!K7 -> 4023.37 | ... R42: ='Dados originais'!R7 -> 4881.37
A45: • DEFASAGEM SALARIAL MENSAL •
A46: AUXILIAR ADMINISTRATIVO OPERACIONAL — 40 HORAS
A47: Classes → | B47: Nível | C47: Regra vertical | D47: I | E47: II | F47: III | G47: IV | H47: V | I47: VI | J47: VII | K47: VIII | L47: IX | M47: X | N47: XI | O47: XII | P47: XIII | Q47: XIV | R47: XV
A48: Níveis ↓ | B48: I | C48: Base | D48: =D19-D28 -> -109.02 | E48: =E19-E28 -> -112.07 | F48: =F19-F28 -> -115.21 | G48: =G19-G28 -> -118.43 | H48: =H19-H28 -> -121.74 | I48: =I19-I28 -> -125.15 | J48: =J19-J28 -> -128.66 | K48: =K19-K28 -> -132.26 | ... R48: =R19-R28 -> -160.46
B49: II | C49: ="+"&TEXT('Parâmetros'!D20,"0.00")&IF('Parâmetros'!C20="valor_fixo"," R$ / ","% / ")&'Parâmetros'!E20 -> +15.00% / I | D49: =D20-D29 -> -125.37 | E49: =E20-E29 -> -128.88 | F49: =F20-F29 -> -132.49 | G49: =G20-G29 -> -136.2 | H49: =H20-H29 -> -140.02 | I49: =I20-I29 -> -143.94 | J49: =J20-J29 -> -147.97 | K49: =K20-K29 -> -152.12 | ... R49: =R20-R29 -> -184.57
B50: III | C50: ="+"&TEXT('Parâmetros'!D21,"0.00")&IF('Parâmetros'!C21="valor_fixo"," R$ / ","% / ")&'Parâmetros'!E21 -> +15.00% / II | D50: =D21-D30 -> -144.18 | E50: =E21-E30 -> -148.22 | F50: =F21-F30 -> -152.36 | G50: =G21-G30 -> -156.63 | H50: =H21-H30 -> -161.01 | I50: =I21-I30 -> -165.52 | J50: =J21-J30 -> -170.15 | K50: =K21-K30 -> -174.92 | ... R50: =R21-R30 -> -212.22
...

Sheet Parâmetros
A1: PARÂMETROS DA COMPARAÇÃO
A3: Município | B3: Curitiba
A4: Profissão/cargo | B4: Auxiliar Administrativo Operacional
A5: Ano | B5: 2026
A6: Jornada do cargo (h/semana) | B6: 40
A7: Tipo da referência | B7: cenario
A8: Nome da referência | B8: Cenário didático: base inicial +5%
A9: Valor da referência | B9: 2289.46
A10: Jornada da referência | B10: 40
A11: Proporcionalidade autorizada | B11: não
A12: Tratamento dos centavos | B12: arredondar
A13: Referência proporcional | B13: =IF(B12="truncar",ROUNDDOWN(IF(B11="sim",B9*B6/B10,B9),2),ROUND(IF(B11="sim",B9*B6/B10,B9),2)) -> 2289.46
A14: Ano da referência | B14: 2026
A15: Tolerância estrutural (R$) | B15: 0.01
A16: Coerência de ano/jornada | B16: =IF(AND(B5=B14,OR(B11="sim",B6=B10)),"OK","REVISAR ANO/JORNADA") -> OK
A18: Nível | B18: Descrição | C18: Regra vertical | D18: Valor (% ou R$) | E18: Sobre o nível
A19: I | B19: Parte permanente — Nível I | C19: base | D19: 0
A20: II | B20: Parte permanente — Nível II | C20: percentual | D20: 15 | E20: I
A21: III | B21: Parte permanente — Nível III | C21: percentual | D21: 15 | E21: II
A22: IV | B22: Parte permanente — Nível IV | C22: percentual | D22: 15 | E22: III
A26: Classe de origem | B26: Classe de destino | C26: Progressão (%)
A27: I | B27: II | C27: 2.8
A28: II | B28: III | C28: 2.8
A29: III | B29: IV | C29: 2.8
A30: IV | B30: V | C30: 2.8
A31: V | B31: VI | C31: 2.8
A32: VI | B32: VII | C32: 2.8
A33: VII | B33: VIII | C33: 2.8
A34: VIII | B34: IX | C34: 2.8
A35: IX | B35: X | C35: 2.8
A36: X | B36: XI | C36: 2.8
A37: XI | B37: XII | C37: 2.8
A38: XII | B38: XIII | C38: 2.8
... A71: XLV | B71: XLVI | C71: 2.8
A74: Cenário/consultoria é uma referência analítica. PSPN é exclusivo do magistério. Alterar profissão, ano ou jornada exige revisar a referência e sua fonte.

Sheet Dados originais
A1: TABELA MUNICIPAL TRANSCRITA — VALORES DE ENTRADA
A3: Nível | B3: Descrição | C3: Regra vertical | D3: I | E3: II | F3: III | G3: IV | H3: V | I3: VI | J3: VII | K3: VIII | L3: IX | M3: X | N3: XI | O3: XII | P3: XIII | Q3: XIV | R3: XV | S3: XVI | T3: XVII | U3: XVIII | V3: XIX | W3: XX | X3: XXI | Y3: XXII | Z3: XXIII | AA3: XXIV | AB3: XXV | AC3: XXVI | AD3: XXVII | AE3: XXVIII | AF3: XXIX | AG3: XXX | AH3: XXXI | AI3: XXXII | AJ3: XXXIII | AK3: XXXIV | AL3: XXXV | AM3: XXXVI | AN3: XXXVII | AO3: XXXVIII | AP3: XXXIX | AQ3: XL | AR3: XLI | AS3: XLII | AT3: XLIII | AU3: XLIV | AV3: XLV | AW3: XLVI
A4: I | B4: Parte permanente — Nível I | C4: base | D4: 2180.44 | E4: 2241.49 | F4: 2304.25 | G4: 2368.77 | H4: 2435.1 | I4: 2503.28 | J4: 2573.37 | K4: 2645.43 | L4: 2719.5 | M4: 2795.65 | N4: 2873.93 | O4: 2954.39 | P4: 3037.12 | Q4: 3122.16 | R4: 3209.58 | S4: 3299.45 | T4: 3391.83 | U4: 3486.8 | V4: 3584.43 | W4: 3684.8 | X4: 3787.97 | Y4: 3894.03 | Z4: 4003.07 | AA4: 4115.15 | AB4: 4230.38 | AC4: 4348.83 | AD4: 4470.59 | AE4: 4595.77 | AF4: 4724.45 | AG4: 4856.74 | AH4: 4992.73 | AI4: 5132.52 | AJ4: 5276.23 | AK4: 5423.97 | AL4: 5575.84 | AM4: 5731.96 | AN4: 5892.46 | AO4: 6057.45 | AP4: 6227.05 | AQ4: 6401.41 | AR4: 6580.65 | AS4: 6764.91 | AT4: 6954.33 | AU4: 7149.05 | AV4: 7349.22 | AW4: 7555
A5: II | B5: Parte permanente — Nível II | C5: percentual | D5: 2507.51 | E5: 2577.72 | F5: 2649.89 | G5: 2724.09 | H5: 2800.36 | I5: 2878.77 | J5: 2959.38 | K5: 3042.24 | L5: 3127.43 | M5: 3214.99 | N5: 3305.01 | O5: 3397.55 | P5: 3492.69 | Q5: 3590.48 | R5: 3691.01 | S5: 3794.36 | T5: 3900.6 | U5: 4009.82 | V5: 4122.1 | W5: 4237.52 | X5: 4356.17 | Y5: 4478.14 | Z5: 4603.53 | AA5: 4732.43 | AB5: 4864.93 | AC5: 5001.15 | AD5: 5141.18 | AE5: 5285.14 | AF5: 5433.12 | AG5: 5585.25 | AH5: 5741.63 | AI5: 5902.4 | AJ5: 6067.67 | AK5: 6237.56 | AL5: 6412.21 | AM5: 6591.76 | AN5: 6776.32 | AO5: 6966.06 | AP5: 7161.11 | AQ5: 7361.62 | AR5: 7567.75 | AS5: 7779.65 | AT5: 7997.48 | AU5: 8221.4 | AV5: 8451.6 | AW5: 8688.25
A6: III | B6: Parte permanente — Nível III | C6: percentual | D6: 2883.63 | E6: 2964.37 | F6: 3047.38 | G6: 3132.7 | H6: 3220.42 | I6: 3310.59 | J6: 3403.29 | K6: 3498.58 | L6: 3596.54 | M6: 3697.24 | N6: 3800.77 | O6: 3907.19 | P6: 4016.59 | Q6: 4129.05 | R6: 4244.67 | S6: 4363.52 | T6: 4485.7 | U6: 4611.3 | V6: 4740.41 | W6: 4873.14 | X6: 5009.59 | Y6: 5149.86 | Z6: 5294.06 | AA6: 5442.29 | AB6: 5594.67 | AC6: 5751.32 | AD6: 5912.36 | AE6: 6077.91 | AF6: 6248.09 | AG6: 6423.04 | AH6: 6602.88 | AI6: 6787.76 | AJ6: 6977.82 | AK6: 7173.2 | AL6: 7374.05 | AM6: 7580.52 | AN6: 7792.77 | AO6: 8010.97 | AP6: 8235.28 | AQ6: 8465.87 | AR6: 8702.91 | AS6: 8946.59 | AT6: 9197.1 | AU6: 9454.62 | AV6: 9719.35 | AW6: 9991.49
A7: IV | B7: Parte permanente — Nível IV | C7: percentual | D7: 3316.18 | E7: 3409.03 | F7: 3504.48 | G7: 3602.61 | H7: 3703.48 | I7: 3807.18 | J7: 3913.78 | K7: 4023.37 | L7: 4136.02 | M7: 4251.83 | N7: 4370.88 | O7: 4493.27 | P7: 4619.08 | Q7: 4748.41 | R7: 4881.37 | S7: 5018.04 | T7: 5158.55 | U7: 5302.99 | V7: 5451.47 | W7: 5604.11 | X7: 5761.03 | Y7: 5922.34 | Z7: 6088.16 | AA7: 6258.63 | AB7: 6433.87 | AC7: 6614.02 | AD7: 6799.22 | AE7: 6989.59 | AF7: 7185.3 | AG7: 7386.49 | AH7: 7593.31 | AI7: 7805.92 | AJ7: 8024.49 | AK7: 8249.18 | AL7: 8480.15 | AM7: 8717.6 | AN7: 8961.69 | AO7: 9212.62 | AP7: 9470.57 | AQ7: 9735.75 | AR7: 10008.35 | AS7: 10288.58 | AT7: 10576.66 | AU7: 10872.81 | AV7: 11177.25 | AW7: 11490.21

Sheet Fontes e premissas
A1: FONTES E DECISÕES ADOTADAS
A3: Organização | B3: Jornada (2).pdf, páginas impressas 9–11: estrutura, atual verde, referência roxa, não conformidades, diferenças e defasagem em vermelho.
A4: Tabela municipal | B4: curitiba.pdf, página 2 (Anexo B1)
A5: URL tabela | B5: https://mid-transparencia.curitiba.pr.gov.br/funcionarios/ano_2026_tabelas_salariais_20260204.pdf
A6: Referência | B6: Hipótese de teste definida pela equipe: 2.180,44 × 1,05. Não é piso legal nem proposta aprovada.
A7: URL referência
A8: Centavos | B8: arredondar em cada etapa. Padrão geral: arredondar. Cafezal: truncar para reproduzir o anexo.
A9: Vigência | B9: 2026; não pressupõe que a tabela histórica seja a mais recente.
A10: Regra da defasagem | B10: (referência / atual - 1) × 100; o destaque usa a classe inicial, conforme o exemplo.
A11: Valores atuais | B11: Transcritos do documento. Permanecem preservados; somente referências são calculadas.
A12: Uso da referência | B12: cenario: Cenário didático: base inicial +5%
A13: Cores de alerta | B13: Vermelho na tabela atual: vencimento abaixo da base de referência. Diferenças da carreira: atual menos referência.
A14: Edição posterior | B14: Ajuste valores, modo e progressões em Parâmetros/Dados originais. Mudança de fonte, profissão, vigência ou quantidade de classes: regenere pelo sistema.
A15: Observação ao gerar | B15: Tabela oficial de janeiro de 2026; não foi confirmada publicação posterior.
A16: Observação ao gerar | B16: Recorte completo da parte permanente do Anexo B1: 4 níveis e 46 referências. Parte especial excluída explicitamente por ter enquadramento distinto.
A17: Observação ao gerar | B17: Progressão horizontal de 2,8% e vertical de 15% inferidas matematicamente para testar o fluxo; a lei deve validar sua aplicação.
A18: Observação ao gerar | B18: O arredondamento comercial foi aplicado em cada etapa; ele pode divergir em centavos de tabelas municipais que usam truncamento.
A19: Observação ao gerar | B19: As progressões entre classes foram inferidas matematicamente; confirme cada percentual na lei municipal.
... A21: Observação ao gerar | B21: A referência aplica as regras de carreira informadas; divergências numéricas não constituem parecer jurídico.
